Workbook

Sheet Teaser
B1: Frasers Group PLC
B2: Frasers Group is a multi-brand sports, premium and international retail group, generating revenue primarily through physical and online retail sales, with additional contributions from Property and Financial Services. UK Sports is the core earnings engine, while International is the key growth driver. The business is working-capital and CapEx intensive due to its large store network and inventory requirements.
B7: Thesis:
B8: Frasers has a mixed credit profile, the gap between EBITDA growth and cash generation remains a key concern. Most segments show revenue or profitability pressure, while International growth carries acquisition and execution risk. Leverage is higher than peers, although current liquidity provides a meaningful buffer and the stress case provide some downside capacity. Credit quality ultimately depends on cash conversion, capital discipline and resilience to weak discretionary retail conditions.
B14: Financial Performance
B15: £m | D15: FY24 | E15: FY25 | F15: FY26
B16: Revenue | D16: 5317 | E16: 4901 | F16: 5326
B17: Revenue Growth | D17: -0.048 | E17: -0.078 | F17: 0.087
B18: EBITDA | D18: 725 | E18: 722 | F18: 836
B19: EBITDA Margin | D19: 0.136 | E19: 0.147 | F19: 0.157
B20: EBIT | D20: 523 | E20: 537 | F20: 629
B21: Net Interest Expense | D21: 8.8 | E21: 16.8 | F21: 136.5
B22: Net Income | D22: 381 | E22: 292 | F22: 375
B24: £m | D24: FY24 | E24: FY25 | F24: FY26
B25: =HistoricalFS!B79 -> Cash from Operations | D25: =HistoricalFS!E79 -> 682.2 | E25: =HistoricalFS!F79 -> 943.4 | F25: =HistoricalFS!G79 -> 583.8
B26: =HistoricalFS!B102 -> FCF (CFO − CapEx) | D26: =HistoricalFS!E102 -> 415 | E26: =HistoricalFS!F102 -> 531.7 | F26: =HistoricalFS!G102 -> -71
B27: =HistoricalFS!B46 -> Cash & Cash Equivalents | D27: =HistoricalFS!E46 -> 358.6 | E27: =HistoricalFS!F46 -> 252.2 | F27: =HistoricalFS!G46 -> 388.9
B29: Segment | C29: 2026 | D29: 2024–26 | E29: 2026
C30: Revenue | D30: Revenue CAGR | E30: Gross margin | F30: Assessment
B31: =Segments!B5 -> UK Sports | C31: =Segments!E6 -> 2570.2 | D31: =Segments!F6 -> -0.060019025 | E31: =Segments!E9 -> 0.511 | F31: Core earnings base, but sustained revenue decline raises concern over demand.
B32: =Segments!B14 -> Premium Lifestyle | C32: =Segments!E15 -> 975.7 | D32: =Segments!F15 -> -0.10928061 | E32: =Segments!E18 -> 0.423 | F32: Contd revenue decline shows weakness in the segment despite strong margin.
B33: =Segments!B23 -> International | C33: =Segments!E24 -> 1603.6 | D33: =Segments!F24 -> 0.2697663 | E33: =Segments!E27 -> 0.437 | F33: Strong revenue growth but stable margins, op loss in 2026
B34: =Segments!B32 -> Property | C34: =Segments!E33 -> 96 | D34: =Segments!F33 -> 0.14912801 | E34: =Segments!E35 -> 1 | F34: Small revenue contributor, limited impact
B35: =Segments!B39 -> Financial Services | C35: =Segments!E40 -> 80.4 | D35: =Segments!F40 -> -0.14892754 | E35: =Segments!E43 -> 0.652 | F35: Significant earnings and profitability deterioration
B53: Capital structure | D53: 2026
B54: Cash | D54: ='Capital structure'!D6 -> 388.9
B55: Borrowings | D55: ='Capital structure'!D7 -> 1651.3
B56: Lease liabilities | D56: ='Capital structure'!D9 -> 878.6
B57: Reported Net Debt | D57: ='Capital structure'!D11 -> 1262.4
B58: Borrowings / EBITDA | D58: ='Capital structure'!D30 -> 1.975003
B59: Net Debt / EBITDA | D59: ='Capital structure'!D31 -> 1.5098672
B60: EBITDA / Net Interest Expense | D60: ='Capital structure'!D33 -> 6.1252747
B62: Funding structure
C63: Term Loan + RCF | F63: Securitisation
B64: Commitment | C64: £3.30bn | F64: £130m
B65: Drawn | C65: £1.56bn | F65: £94m
B66: Purpose | C66: Corporate / general liquidity | F66: Consumer-credit funding
B67: Security | C67: Not specifically disclosed | F67: Secured against eligible consumer-credit receivables
B68: Maturity/Availability | C68: 47300 | F68: Dec-26 drawing availability
B69: Pricing | C69: 1.75% + relevant interbank rate | F69: 2.4% + SONIA
...

Sheet Analysis>

Sheet HistoricalFS
B5: Historical Financial Statements - Snapshot
B6: Years | C6: 2022 | D6: 2023 | E6: 2024 | F6: 2025 | G6: 2026
B8: Income statement
B10: Total Revenues | C10: ='Data Sheet'!D9 -> 4805.3 | D10: ='Data Sheet'!E9 -> 5586 | E10: ='Data Sheet'!F9 -> 5317 | F10: ='Data Sheet'!G9 -> 4900.9 | G10: ='Data Sheet'!H9 -> 5325.9
B11: Total Revenues Growth | C11: ='Data Sheet'!D10 -> 0.3255 | D11: ='Data Sheet'!E10 -> 0.1625 | E11: ='Data Sheet'!F10 -> -0.0482 | F11: ='Data Sheet'!G10 -> -0.0783 | G11: ='Data Sheet'!H10 -> 0.0867
B13: COGS | C13: ='Data Sheet'!D11 -> 2708.1 | D13: ='Data Sheet'!E11 -> 3175.5 | E13: ='Data Sheet'!F11 -> 2887.2 | F13: ='Data Sheet'!G11 -> 2587.5 | G13: ='Data Sheet'!H11 -> 2721.6
B15: Gross Profit | C15: =C10-C13 -> 2097.2 | D15: =D10-D13 -> 2410.5 | E15: =E10-E13 -> 2429.8 | F15: =F10-F13 -> 2313.4 | G15: =G10-G13 -> 2604.3
B16: Gross Profit Growth | C16: ='Data Sheet'!D13 -> 0.37 | D16: ='Data Sheet'!E13 -> 0.1494 | E16: ='Data Sheet'!F13 -> 0.008 | F16: ='Data Sheet'!G13 -> -0.0479 | G16: ='Data Sheet'!H13 -> 0.1257
B17: Gross Profit Margin % | C17: ='Data Sheet'!D14 -> 0.4364 | D17: ='Data Sheet'!E14 -> 0.4315 | E17: ='Data Sheet'!F14 -> 0.457 | F17: ='Data Sheet'!G14 -> 0.472 | G17: ='Data Sheet'!H14 -> 0.489
B19: Operating Expenses | C19: ='Data Sheet'!D15 -> 1554 | D19: ='Data Sheet'!E15 -> 1961.6 | E19: ='Data Sheet'!F15 -> 1906.6 | F19: ='Data Sheet'!G15 -> 1776.9 | G19: ='Data Sheet'!H15 -> 1975.5
B21: EBITDA | C21: ='Data Sheet'!D46 -> 725.6 | D21: ='Data Sheet'!E46 -> 642.9 | E21: ='Data Sheet'!F46 -> 724.6 | F21: ='Data Sheet'!G46 -> 722.3 | G21: ='Data Sheet'!H46 -> 836.1
B22: EBITDA Growth | C22: ='Data Sheet'!D47 -> 0.5321 | D22: ='Data Sheet'!E47 -> -0.114 | E22: ='Data Sheet'!F47 -> 0.1271 | F22: ='Data Sheet'!G47 -> -0.0032 | G22: ='Data Sheet'!H47 -> 0.1576
B23: EBITDA Margin % | C23: ='Data Sheet'!D48 -> 0.151 | D23: ='Data Sheet'!E48 -> 0.1151 | E23: ='Data Sheet'!F48 -> 0.1363 | F23: ='Data Sheet'!G48 -> 0.1474 | G23: ='Data Sheet'!H48 -> 0.157
B25: Depreciation & Amortisation | C25: =C21-C27 -> 182.4 | D25: =D21-D27 -> 194 | E25: =E21-E27 -> 201.4 | F25: =F21-F27 -> 185.8 | G25: =G21-G27 -> 207.3
B27: EBIT | C27: ='Data Sheet'!D49 -> 543.2 | D27: ='Data Sheet'!E49 -> 448.9 | E27: ='Data Sheet'!F49 -> 523.2 | F27: ='Data Sheet'!G49 -> 536.5 | G27: ='Data Sheet'!H49 -> 628.8
B28: EBIT Margin % | C28: =C27/C10 -> 0.11304185 | D28: =D27/D10 -> 0.080361618 | E28: =E27/E10 -> 0.098401354 | F28: =F27/F10 -> 0.10946969 | G28: =G27/G10 -> 0.11806455
B30: Net Interest Expenses | C30: ='Data Sheet'!D19 -> 15.5 | D30: ='Data Sheet'!E19 -> 61.7 | E30: ='Data Sheet'!F19 -> 8.8 | F30: ='Data Sheet'!G19 -> 16.8 | G30: ='Data Sheet'!H19 -> 136.5
B31: Net Interest Expenses Growth | C31: ='Data Sheet'!D20 -> -0.7952 | D31: ='Data Sheet'!E20 -> 2.9806 | E31: ='Data Sheet'!F20 -> -0.8574 | F31: ='Data Sheet'!G20 -> 0.9091 | G31: ='Data Sheet'!H20 -> 7.125
B33: Interest Expense, Total | C33: ='Data Sheet'!D21 -> -32.8 | D33: ='Data Sheet'!E21 -> -60.6 | E33: ='Data Sheet'!F21 -> -85.4 | F33: ='Data Sheet'!G21 -> -111.6 | G33: ='Data Sheet'!H21 -> -150.8
B35: EBT, Incl. Unusual Items | C35: ='Data Sheet'!D27 -> 335.6 | D35: ='Data Sheet'!E27 -> 638 | E35: ='Data Sheet'!F27 -> 501 | F35: ='Data Sheet'!G27 -> 379.9 | G35: ='Data Sheet'!H27 -> 527.8
B37: Income Tax Expense | C37: ='Data Sheet'!D30 -> 78.7 | D37: ='Data Sheet'!E30 -> 159.3 | E37: ='Data Sheet'!F30 -> 107.9 | F37: ='Data Sheet'!G30 -> 92.7 | G37: ='Data Sheet'!H30 -> 184
B39: Net Income | C39: ='Data Sheet'!D33 -> 249.8 | D39: ='Data Sheet'!E33 -> 491.7 | E39: ='Data Sheet'!F33 -> 380.8 | F39: ='Data Sheet'!G33 -> 292.1 | G39: ='Data Sheet'!H33 -> 375
B40: Net Income Growth | C40: ='Data Sheet'!D34 -> 4.0096 | D40: ='Data Sheet'!E34 -> 0.9684 | E40: ='Data Sheet'!F34 -> -0.2255 | F40: ='Data Sheet'!G34 -> -0.2329 | G40: ='Data Sheet'!H34 -> 0.2838
B41: Net Income Margin % | C41: ='Data Sheet'!D35 -> 0.052 | D41: ='Data Sheet'!E35 -> 0.088 | E41: ='Data Sheet'!F35 -> 0.0716 | F41: ='Data Sheet'!G35 -> 0.0596 | G41: ='Data Sheet'!H35 -> 0.0704
B43: Balance Sheet
B45: Total Current Assets | C45: ='Data Sheet'!D56 -> 2612.3 | D45: ='Data Sheet'!E56 -> 2597.2 | E45: ='Data Sheet'!F56 -> 2476 | F45: ='Data Sheet'!G56 -> 2355.6 | G45: ='Data Sheet'!H56 -> 2701.1
B46: Cash & Cash Equivalents | C46: ='Data Sheet'!D57 -> 336.8 | D46: ='Data Sheet'!E57 -> 332.9 | E46: ='Data Sheet'!F57 -> 358.6 | F46: ='Data Sheet'!G57 -> 252.2 | G46: ='Data Sheet'!H57 -> 388.9
B47: Total Receivables | C47: ='Data Sheet'!D60 -> 485 | D47: ='Data Sheet'!E60 -> 418.5 | E47: ='Data Sheet'!F60 -> 432.5 | F47: ='Data Sheet'!G60 -> 318.1 | G47: ='Data Sheet'!H60 -> 526.9
B48: Inventory | C48: ='Data Sheet'!D63 -> 1277.6 | D48: ='Data Sheet'!E63 -> 1464.9 | E48: ='Data Sheet'!F63 -> 1355.3 | F48: ='Data Sheet'!G63 -> 1128.3 | G48: ='Data Sheet'!H63 -> 1279.8
B49: Other Current Assets, Total | C49: ='Data Sheet'!D69 -> 400.4 | D49: ='Data Sheet'!E69 -> 240.7 | E49: ='Data Sheet'!F69 -> 204.9 | F49: ='Data Sheet'!G69 -> 561.8 | G49: ='Data Sheet'!H69 -> 408.7
B51: Total Assets | C51: ='Data Sheet'!D70 -> 4142.7 | D51: ='Data Sheet'!E70 -> 4302.7 | E51: ='Data Sheet'!F70 -> 4454.9 | F51: ='Data Sheet'!G70 -> 5130.7 | G51: ='Data Sheet'!H70 -> 6486.5
B52: Net Property Plant And Equipment | C52: ='Data Sheet'!D72 -> 1011 | D52: ='Data Sheet'!E72 -> 1132 | E52: ='Data Sheet'!F72 -> 962.6 | F52: ='Data Sheet'!G72 -> 1097.2 | G52: ='Data Sheet'!H72 -> 1426.1
B53: Long-Term Investments | C53: ='Data Sheet'!D75 -> 206.6 | D53: ='Data Sheet'!E75 -> 306.5 | E53: ='Data Sheet'!F75 -> 513.4 | F53: ='Data Sheet'!G75 -> 995.5 | G53: ='Data Sheet'!H75 -> 1280.1
B54: Intangible Assets | C54: ='Data Sheet'!D76 -> 120.6 | D54: ='Data Sheet'!E76 -> 24.1 | E54: ='Data Sheet'!F76 -> 42.2 | F54: ='Data Sheet'!G76 -> 58.5 | G54: ='Data Sheet'!H76 -> 99.4
B55: Goodwill | C55: ='Data Sheet'!D77 -> 44.4 | D55: ='Data Sheet'!E77 -> 9.9 | E55: ='Data Sheet'!F77 -> 9.9 | F55: ='Data Sheet'!G77 -> 30.4 | G55: ='Data Sheet'!H77 -> 81
B56: Other Assets, Total | C56: ='Data Sheet'!D80 -> 192.2 | D56: ='Data Sheet'!E80 -> 242.9 | E56: ='Data Sheet'!F80 -> 460.7 | F56: ='Data Sheet'!G80 -> 623.9 | G56: ='Data Sheet'!H80 -> 979.8
B58: Total Current Liabilities | C58: ='Data Sheet'!D86 -> 1027.6 | D58: ='Data Sheet'!E86 -> 1016.9 | E58: ='Data Sheet'!F86 -> 964.8 | F58: ='Data Sheet'!G86 -> 1236.8 | G58: ='Data Sheet'!H86 -> 1500.4
B59: Accounts Payable, Total | C59: ='Data Sheet'!D87 -> 358.1 | D59: ='Data Sheet'!E87 -> 375 | E59: ='Data Sheet'!F87 -> 335.7 | F59: ='Data Sheet'!G87 -> 339.9 | G59: ='Data Sheet'!H87 -> 457.7
B60: Accrued Expenses, Total | C60: ='Data Sheet'!D88 -> 269.6 | D60: ='Data Sheet'!E88 -> 240.9 | E60: ='Data Sheet'!F88 -> 231.7 | F60: ='Data Sheet'!G88 -> 253.9 | G60: ='Data Sheet'!H88 -> 312.8
B61: Short-Term Borrowings | C61: ='Data Sheet'!D89 -> - | D61: ='Data Sheet'!E89 -> - | E61: ='Data Sheet'!F89 -> - | F61: ='Data Sheet'!G89 -> - | G61: ='Data Sheet'!H89 -> -
...

Sheet Segments
B2: Segment Analysis
C3: 2024 | D3: 2025 | E3: 2026 | F3: CAGR | H3: FOR TEASER PAGE
B5: ='Data Sheet'!C170 -> UK Sports | H5: Segment Credit Profile
B6: ='Data Sheet'!C171 -> Revenue | C6: ='Data Sheet'!D171 -> 2908.9 | D6: ='Data Sheet'!E171 -> 2698.1 | E6: ='Data Sheet'!F171 -> 2570.2 | F6: =(E6/C6)^(1/2)-1 -> -0.060019025 | O6: UK Sports remains the core earnings contributor, with improving trading and operating profitability despite revenue contraction.
B7: ='Data Sheet'!C172 -> Cost of sales | C7: ='Data Sheet'!D172 -> -1558.5 | D7: ='Data Sheet'!E172 -> -1398.5 | E7: ='Data Sheet'!F172 -> -1256
B8: ='Data Sheet'!C173 -> Gross profit | C8: ='Data Sheet'!D173 -> 1350.4 | D8: ='Data Sheet'!E173 -> 1299.6 | E8: ='Data Sheet'!F173 -> 1314.2 | F8: =(E8/C8)^(1/2)-1 -> -0.013494487 | O8: International has become a major growth driver, increasing its revenue contribution from 18.7% to 30.1%, but FY26 operating losses represent a key credit risk.
B9: ='Data Sheet'!C174 -> Gross margin % | C9: ='Data Sheet'!D174 -> 0.464 | D9: ='Data Sheet'!E174 -> 0.482 | E9: ='Data Sheet'!F174 -> 0.511
B10: ='Data Sheet'!C175 -> Profit from trading | C10: ='Data Sheet'!D175 -> 468.4 | D10: ='Data Sheet'!E175 -> 475.8 | E10: ='Data Sheet'!F175 -> 559.4 | O10: Financial Services has experienced significant earnings deterioration alongside higher credit receivable impairments, while Premium Lifestyle shows weaker revenue but relatively resilient profitability.
B11: ='Data Sheet'!C176 -> Operating profit | C11: ='Data Sheet'!D176 -> 353.1 | D11: ='Data Sheet'!E176 -> 365.5 | E11: ='Data Sheet'!F176 -> 387.1 | F11: =(E11/C11)^(1/2)-1 -> 0.047038683
B12: ='Data Sheet'!C177 -> Store numbers | C12: ='Data Sheet'!D177 -> 797 | D12: ='Data Sheet'!E177 -> 785 | E12: ='Data Sheet'!F177 -> 794
B14: ='Data Sheet'!C179 -> Premium Lifestyle
B15: ='Data Sheet'!C180 -> Revenue | C15: ='Data Sheet'!D180 -> 1229.8 | D15: ='Data Sheet'!E180 -> 1048.2 | E15: ='Data Sheet'!F180 -> 975.7 | F15: =(E15/C15)^(1/2)-1 -> -0.10928061 | H15: Revenue Mix | I15: 2024 | J15: 2024 Mix | K15: 2026 | L15: 2026 Mix
B16: ='Data Sheet'!C181 -> Cost of sales | C16: ='Data Sheet'!D181 -> -773.2 | D16: ='Data Sheet'!E181 -> -635.4 | E16: ='Data Sheet'!F181 -> -563 | H16: =Teaser!B31 -> UK Sports | I16: =C6 -> 2908.9 | J16: =I16/$I$21 -> 0.54709423 | K16: =E6 -> 2570.2 | L16: =K16/$K$21 -> 0.4825851
B17: ='Data Sheet'!C182 -> Gross profit | C17: ='Data Sheet'!D182 -> 456.6 | D17: ='Data Sheet'!E182 -> 412.8 | E17: ='Data Sheet'!F182 -> 412.7 | F17: =(E17/C17)^(1/2)-1 -> -0.049287332 | H17: =Teaser!B32 -> Premium Lifestyle | I17: =C15 -> 1229.8 | J17: =I17/$I$21 -> 0.23129584 | K17: =E15 -> 975.7 | L17: =K17/$K$21 -> 0.18319908
B18: ='Data Sheet'!C183 -> Gross margin % | C18: ='Data Sheet'!D183 -> 0.371 | D18: ='Data Sheet'!E183 -> 0.394 | E18: ='Data Sheet'!F183 -> 0.423 | H18: =Teaser!B33 -> International | I18: =C24 -> 994.6 | J18: =I18/$I$21 -> 0.18706037 | K18: =E24 -> 1603.6 | L18: =K18/$K$21 -> 0.30109465
B19: ='Data Sheet'!C184 -> Profit from trading | C19: ='Data Sheet'!D184 -> 137.2 | D19: ='Data Sheet'!E184 -> 157.4 | E19: ='Data Sheet'!F184 -> 147.6 | H19: =Teaser!B34 -> Property | I19: =C33 -> 72.7 | J19: =I19/$I$21 -> 0.013673124 | K19: =E33 -> 96 | L19: =K19/$K$21 -> 0.018025123
B20: ='Data Sheet'!C185 -> Operating profit | C20: ='Data Sheet'!D185 -> 98.6 | D20: ='Data Sheet'!E185 -> 131.9 | E20: ='Data Sheet'!F185 -> 102.1 | F20: =(E20/C20)^(1/2)-1 -> 0.017593709 | H20: =Teaser!B35 -> Financial Services | I20: =C40 -> 111 | J20: =I20/$I$21 -> 0.020876434 | K20: =E40 -> 80.4 | L20: =K20/$K$21 -> 0.01509604
B21: ='Data Sheet'!C186 -> Store numbers | C21: ='Data Sheet'!D186 -> 181 | D21: ='Data Sheet'!E186 -> 156 | E21: ='Data Sheet'!F186 -> 133 | H21: Total | I21: =SUM(I16:I20) -> 5317 | K21: =SUM(K16:K20) -> 5325.9
B23: ='Data Sheet'!C188 -> International | H23: Year | I23: =H16 -> UK Sports | J23: =H17 -> Premium Lifestyle | K23: =H18 -> International | L23: =H19 -> Property | M23: =H20 -> Financial Services
B24: ='Data Sheet'!C189 -> Revenue | C24: ='Data Sheet'!D189 -> 994.6 | D24: ='Data Sheet'!E189 -> 1007.4 | E24: ='Data Sheet'!F189 -> 1603.6 | F24: =(E24/C24)^(1/2)-1 -> 0.2697663 | H24: =J15 -> 2024 Mix | I24: =J16 -> 0.54709423 | J24: =J17 -> 0.23129584 | K24: =J18 -> 0.18706037 | L24: =J19 -> 0.013673124 | M24: =J20 -> 0.020876434
B25: ='Data Sheet'!C190 -> Cost of sales | C25: ='Data Sheet'!D190 -> -547.7 | D25: ='Data Sheet'!E190 -> -553.6 | E25: ='Data Sheet'!F190 -> -902.9 | H25: =L15 -> 2026 Mix | I25: =L16 -> 0.4825851 | J25: =L17 -> 0.18319908 | K25: =L18 -> 0.30109465 | L25: =L19 -> 0.018025123 | M25: =L20 -> 0.01509604
B26: ='Data Sheet'!C191 -> Gross profit | C26: ='Data Sheet'!D191 -> 446.9 | D26: ='Data Sheet'!E191 -> 453.8 | E26: ='Data Sheet'!F191 -> 700.7 | F26: =(E26/C26)^(1/2)-1 -> 0.25216304
B27: ='Data Sheet'!C192 -> Gross margin % | C27: ='Data Sheet'!D192 -> 0.449 | D27: ='Data Sheet'!E192 -> 0.45 | E27: ='Data Sheet'!F192 -> 0.437
B28: ='Data Sheet'!C193 -> Profit from trading | C28: ='Data Sheet'!D193 -> 127.2 | D28: ='Data Sheet'!E193 -> 114.1 | E28: ='Data Sheet'!F193 -> 205.5
B29: ='Data Sheet'!C194 -> Operating (loss)/profit | C29: ='Data Sheet'!D194 -> 38.1 | D29: ='Data Sheet'!E194 -> 38.1 | E29: ='Data Sheet'!F194 -> -152.2
B30: ='Data Sheet'!C195 -> Store numbers | C30: ='Data Sheet'!D195 -> 350 | D30: ='Data Sheet'!E195 -> 373 | E30: ='Data Sheet'!F195 -> 565
B32: ='Data Sheet'!C197 -> Property
B33: ='Data Sheet'!C198 -> Revenue | C33: ='Data Sheet'!D198 -> 72.7 | D33: ='Data Sheet'!E198 -> 61.9 | E33: ='Data Sheet'!F198 -> 96 | F33: =(E33/C33)^(1/2)-1 -> 0.14912801
B34: ='Data Sheet'!C199 -> Gross profit | C34: ='Data Sheet'!D199 -> 64.9 | D34: ='Data Sheet'!E199 -> 61.9 | E34: ='Data Sheet'!F199 -> 96 | F34: =(E34/C34)^(1/2)-1 -> 0.21622316
B35: ='Data Sheet'!C200 -> Gross margin % | C35: ='Data Sheet'!D200 -> 0.893 | D35: ='Data Sheet'!E200 -> 1 | E35: ='Data Sheet'!F200 -> 1
B36: ='Data Sheet'!C201 -> Profit from trading | C36: ='Data Sheet'!D201 -> 39.1 | D36: ='Data Sheet'!E201 -> 43.1 | E36: ='Data Sheet'!F201 -> 85.7
B37: ='Data Sheet'!C202 -> Operating profit | C37: ='Data Sheet'!D202 -> -31.3 | D37: ='Data Sheet'!E202 -> 5 | E37: ='Data Sheet'!F202 -> 41.5
B39: ='Data Sheet'!C204 -> Financial Services
B40: ='Data Sheet'!C205 -> Revenue | C40: ='Data Sheet'!D205 -> 111 | D40: ='Data Sheet'!E205 -> 85.3 | E40: ='Data Sheet'!F205 -> 80.4 | F40: =(E40/C40)^(1/2)-1 -> -0.14892754
B41: ='Data Sheet'!C206 -> Impairment losses on credit receivables | C41: ='Data Sheet'!D206 -> -20.6 | D41: ='Data Sheet'!E206 -> -22.1 | E41: ='Data Sheet'!F206 -> -28
B42: ='Data Sheet'!C207 -> Gross profit | C42: ='Data Sheet'!D207 -> 90.4 | D42: ='Data Sheet'!E207 -> 63.2 | E42: ='Data Sheet'!F207 -> 52.4 | F42: =(E42/C42)^(1/2)-1 -> -0.23865513
B43: ='Data Sheet'!C208 -> Gross margin % | C43: ='Data Sheet'!D208 -> 0.814 | D43: ='Data Sheet'!E208 -> 0.741 | E43: ='Data Sheet'!F208 -> 0.652
B44: ='Data Sheet'!C209 -> Profit from trading | C44: ='Data Sheet'!D209 -> 57.6 | D44: ='Data Sheet'!E209 -> 17.5 | E44: ='Data Sheet'!F209 -> 7.7
B45: ='Data Sheet'!C210 -> Operating profit | C45: ='Data Sheet'!D210 -> 56.1 | D45: ='Data Sheet'!E210 -> 17 | E45: ='Data Sheet'!F210 -> 7.8 | F45: =(E45/C45)^(1/2)-1 -> -0.62712276

Sheet Capital structure
B3: =HistoricalFS!B21 -> EBITDA | C3: =HistoricalFS!F21 -> 722.3 | D3: =HistoricalFS!G21 -> 836.1
B5: ='Data Sheet'!C212 -> CAPITAL STRUCTURE | C5: 2025 | D5: ='Data Sheet'!E212 -> 2026
B6: ='Data Sheet'!C213 -> Cash & cash equivalents | C6: ='Data Sheet'!D213 -> 252.2 | D6: ='Data Sheet'!E213 -> 388.9
B7: Borrowings | C7: ='Data Sheet'!D214 -> 1193.2 | D7: ='Data Sheet'!E214 -> 1651.3
B8: Securitisation (incl in borrowings) | C8: ='Data Sheet'!D215 -> 93.5 | D8: ='Data Sheet'!E215 -> 94.3
B9: ='Data Sheet'!C216 -> Lease liabilities | C9: ='Data Sheet'!D216 -> 667.8 | D9: ='Data Sheet'!E216 -> 878.6
B10: ='Data Sheet'!C217 -> Total debt incl. leases | C10: ='Data Sheet'!D217 -> 1861 | D10: ='Data Sheet'!E217 -> 2529.9
B11: ='Data Sheet'!C218 -> Net debt | C11: ='Data Sheet'!D218 -> 941 | D11: ='Data Sheet'!E218 -> 1262.4
B12: ='Data Sheet'!C219 -> Net debt excl. securitisation | C12: ='Data Sheet'!D219 -> 847.5 | D12: ='Data Sheet'!E219 -> 1168.1
B13: ='Data Sheet'!C220 -> Net assets / Equity | C13: ='Data Sheet'!D220 -> 1988.1 | D13: ='Data Sheet'!E220 -> 2452.7
B15: ='Data Sheet'!C222 -> CAPITAL STRUCTURE
B16: ='Data Sheet'!C223 -> Facility | C16: ='Data Sheet'!D223 -> Type / Purpose | D16: ='Data Sheet'!E223 -> Committed Limit | E16: ='Data Sheet'!F223 -> FY26 Drawn | F16: ='Data Sheet'!G223 -> Maturity / Availability | G16: ='Data Sheet'!H223 -> Pricing | H16: ='Data Sheet'!I223 -> Security
B17: ='Data Sheet'!C224 -> Term Loan + RCF | C17: ='Data Sheet'!D224 -> Corporate funding / general liquidity | D17: ='Data Sheet'!E224 -> 3300 | E17: ='Data Sheet'!F224 -> 1557 | F17: ='Data Sheet'!G224 -> 47300 | G17: ='Data Sheet'!H224 -> 1.75% + relevant interbank rate | H17: ='Data Sheet'!I224 -> Not specifically disclosed
B18: ='Data Sheet'!C225 -> Securitisation Facility | C18: ='Data Sheet'!D225 -> Funding of consumer-credit receivables | D18: ='Data Sheet'!E225 -> 130 | E18: ='Data Sheet'!F225 -> 94.3 | F18: ='Data Sheet'!G225 -> New drawings available until Dec-26 | G18: ='Data Sheet'!H225 -> 2.4% + SONIA | H18: ='Data Sheet'!I225 -> Secured against eligible consumer-credit receivables
B22: ='Data Sheet'!C227 -> DEBT MATURITY
C23: ='Data Sheet'!D228 -> <1 year | D23: ='Data Sheet'!E228 -> 1–2 years | E23: ='Data Sheet'!F228 -> 2–5 years | F23: ='Data Sheet'!G228 -> >5 years | G23: ='Data Sheet'!H228 -> Total
B24: ='Data Sheet'!C229 -> Bank loan principal | C24: ='Data Sheet'!D229 -> - | D24: ='Data Sheet'!E229 -> - | E24: ='Data Sheet'!F229 -> 1651.3 | F24: ='Data Sheet'!G229 -> - | G24: ='Data Sheet'!H229 -> 1651.3
B25: ='Data Sheet'!C230 -> Bank loan interest | C25: ='Data Sheet'!D230 -> 94 | D25: ='Data Sheet'!E230 -> 99.3 | E25: ='Data Sheet'!F230 -> 105 | F25: ='Data Sheet'!G230 -> - | G25: ='Data Sheet'!H230 -> 298.3
B26: ='Data Sheet'!C231 -> IFRS 16 lease liabilities | C26: ='Data Sheet'!D231 -> 195.7 | D26: ='Data Sheet'!E231 -> 177.3 | E26: ='Data Sheet'!F231 -> 330.4 | F26: ='Data Sheet'!G231 -> 646.7 | G26: ='Data Sheet'!H231 -> 1350.1
B27: ='Data Sheet'!C232 -> Total contractual cash outflow | C27: ='Data Sheet'!D232 -> 289.7 | D27: ='Data Sheet'!E232 -> 276.6 | E27: ='Data Sheet'!F232 -> 2086.7 | F27: ='Data Sheet'!G232 -> 646.7 | G27: ='Data Sheet'!H232 -> 3299.7
B29: Credit Metrics | C29: 2025 | D29: 2026
B30: Borrowings / EBITDA | C30: =C7/C3 -> 1.6519452 | D30: =D7/D3 -> 1.975003
B31: Net Debt / EBITDA | C31: =C11/C3 -> 1.3027828 | D31: =D11/D3 -> 1.5098672
B32: Net Debt excl. Securitisation / EBITDA | C32: =C12/C3 -> 1.1733352 | D32: =D12/D3 -> 1.3970817
B33: EBITDA / Net Interest Expenses | C33: =HistoricalFS!F21/HistoricalFS!F30 -> 42.994048 | D33: =HistoricalFS!G21/HistoricalFS!G30 -> 6.1252747
B34: EBIT / Interest Expense, Total | C34: =HistoricalFS!F27/HistoricalFS!F33 -> -4.8073477 | D34: =HistoricalFS!G27/HistoricalFS!G33 -> -4.1697613
B35: Cash Flow from Operations / Total Debt | C35: =HistoricalFS!F79/'Capital structure'!C10 -> 0.50693176 | D35: =HistoricalFS!G79/'Capital structure'!D10 -> 0.23076011
B36: Levered Free Cash Flow / Total Debt | C36: =HistoricalFS!F100/'Capital structure'!C10 -> 0.17778614 | D36: =HistoricalFS!G100/'Capital structure'!D10 -> 0.022589826
B38: Frasers Group states that it operates within its banking facilities and covenants. The FY26 Annual Report identifies net debt/EBITDA and interest cover as the financial covenants but does not disclose the numerical thresholds.
B41: FOR THE TEASER

Sheet Peer Analysis
B4: Comparable Companies
B5: JD Sports Fashion | C5: UK-listed international sports and fashion retailer with a large store and omnichannel footprint, exposure to branded sportswear, inventory and discretionary consumer spending. Its operating model and consumer exposure make it the closest direct comparable to Frasers.
B7: Marks & Spencer | C7: Large UK-listed multi-category retailer with significant physical-store and omnichannel operations. Useful for benchmarking UK consumer demand, retail margins, working capital, leases and cash generation.
B9: Next PLC | C9: UK-listed fashion and omnichannel retailer with exposure to apparel, online retail, stores, inventory and discretionary consumer spending. Useful for comparing fashion-retail profitability and cash generation.
B21: Frasers has the lowest revenue among the selected peer set but strong operating profitability.
B22: Its debt-servicing capacity is comfortable, but its higher leverage reduces balance-sheet flexibility versus lower-leveraged peers.

Sheet Drivers
B4: INDUSTRY OVERVIEW
B5: UK and European consumers are increasingly favouring value or premium offerings, creating pressure on mid-market discretionary retail.
B6: Rising wages, business rates, energy and logistics costs continue to put pressure on retail margins.
B7: Weak consumer demand has increased inventory levels across apparel and sportswear, leading to higher discounting and margin pressure.
B8: Major sportswear brands are increasing direct-to-consumer sales
B10: DRIVERS
B11: Positive for Credit | C11: Negative for Credit
B12: Sportswear demand resilience: Continued demand for sportswear supports Frasers’ core UK Sports revenue and cash generation. | C12: UK retail demand is weakening: September 2026 UK retailers reported their sharpest sales decline since April amid weak consumer sentiment.
B13: International retail expansion: Growing sports retail markets outside the UK provide revenue diversification and additional earnings capacity. | C13: Retail cost pressures remain elevated: energy, employment and other input costs are rising, creating margin pressure for retailers.
B14: Stronger product and brand mix (value & premium brands) is supporting gross-margin resilience and cash generation. | C14: Supplier disintermediation: Global brands increasingly selling directly to consumers could weaken Frasers’ product access and bargaining position.
B15: Recovery in Premium/Luxury demand could improve earnings diversification and reduce pressure on group profitability. | C15: Acquisition/integration risk could create additional cash requirements before acquired businesses contribute earnings.
B17: KEY RISKS & MITIGANTS
B18: Acquisitions and strategic investments can consume liquidity and increase leverage. | C18: High underlying free cash flow generation from core operations, combined with substantial tangible asset collateral across owned real estate.
B19: A vast stores network creates heavy, inflexible IFRS 16 lease liabilities, acting as rigid fixed financial obligations. | C19: closure or renegotiation of underperforming stores can reduce the burden.
B20: Rapidly expanding Frasers Plus (buy-now-pay-later) increases exposure to customer defaults and bad debt. | C20: Customer transaction data and credit controls support underwriting and risk management.
B21: Slow-moving or seasonal inventory can require discounting, reducing margins and tying up working capital. | C21: Sports Direct's high-volume model and focus on staple sportswear reduces exposure to severe fashion obsolescence
B22: Heavy exposure to the UK consumer economy makes earnings vulnerable to a domestic slowdown. | C22: International expansion across Europe and other markets is diversifying the Group's revenue base.

Sheet Scenario Analysis
B3: Scenario Analysis - EBITDA Stress Test | G3: Assumptions
B4: Metric | C4: Base (2026) | D4: Downside | E4: Severe Downside | G4: Revenue and net debt held constant to isolate EBITDA sensitivity
B5: Revenue | C5: =HistoricalFS!G10 -> 5325.9 | D5: =C5 -> 5325.9 | E5: =D5 -> 5325.9 | G5: Liquidity held constant before any additional cash burn or facility drawings under stress.
B6: EBITDA | C6: =HistoricalFS!G21 -> 836.1 | D6: =C6*(1+D7) -> 668.88 | E6: =C6*(1+E7) -> 501.66
B7: change | D7: -0.2 | E7: -0.4 | G7: Base
B8: EBITDA Margin | C8: =HistoricalFS!G23 -> 0.157 | D8: =D6/HistoricalFS!G10 -> 0.12559004 | E8: =E6/HistoricalFS!G10 -> 0.094192531
B9: Net Debt | C9: ='Capital structure'!D11 -> 1262.4 | D9: =C9 -> 1262.4 | E9: =D9 -> 1262.4 | G9: 1.51x net leverage and 6.13x interest coverage indicate substantial debt-service capacity.
B10: Net Debt / EBITDA | C10: ='Capital structure'!D31 -> 1.5098672 | D10: =D9/D6 -> 1.8873341 | E10: =E9/E6 -> 2.5164454
B11: Net Interest Expense | C11: =HistoricalFS!G30 -> 136.5 | D11: =C11 -> 136.5 | E11: =D11 -> 136.5 | G11: Downside
B12: EBITDA/Net Interest Exp | C12: ='Capital structure'!D33 -> 6.1252747 | D12: =D6/D11 -> 4.9002198 | E12: =E6/E11 -> 3.6751648
B13: Liquidity | C13: =HistoricalFS!G46+B15 -> 2131.9 | D13: =C13 -> 2131.9 | E13: =D13 -> 2131.9 | G13: A 20% EBITDA decline increases leverage to 1.89x and reduces interest coverage to 4.90x, but debt-service capacity remains supported.
B15: 1743 | C15: undrawn bank facilities | G15: Severe Downside
G17: A 40% EBITDA decline increases leverage to 2.52x and reduces interest coverage to 3.68x, materially reducing financial flexibility.
G18: Severe downside leverage reaches 2.52x, remaining below Frasers' stated 3.0x net debt / Reported EBITDA level.
B22: Corporate Bank Exposure
B23: Total borrowings | C23: ='Capital structure'!D7 -> 1651.3
B24: Less: securitization | C24: ='Capital structure'!D8 -> 94.3
B25: Corporate bank exposure | C25: =C23-C24 -> 1557
B27: ='Data Sheet'!C246 -> Asset | C27: ='Data Sheet'!D246 -> Carrying Value | D27: Recovery % | E27: Recoverable Value
B28: ='Data Sheet'!C247 -> Cash | C28: ='Data Sheet'!D247 -> 388.9 | D28: 1 | E28: =D28*C28 -> 388.9
B29: ='Data Sheet'!C248 -> Receivables | C29: ='Data Sheet'!D248 -> 978.8 | D29: 0.6 | E29: =D29*C29 -> 587.28
B30: ='Data Sheet'!C249 -> Inventory | C30: ='Data Sheet'!D249 -> 1279.8 | D30: 0.4 | E30: =D30*C30 -> 511.92
B31: ='Data Sheet'!C250 -> PP&E | C31: ='Data Sheet'!D250 -> 1426.1 | D31: 0.55 | E31: =D31*C31 -> 784.355
B32: ='Data Sheet'!C251 -> Investment properties | C32: ='Data Sheet'!D251 -> 852.2 | D32: 0.6 | E32: =D32*C32 -> 511.32 | G32: Recovery appears supported by a sizeable and diversified asset base, but remains sensitive to asset haircuts and creditor ranking given the lack of a disclosed specific collateral package for the corporate term loan/RCF.
B33: ='Data Sheet'!C252 -> Long-term financial assets | C33: ='Data Sheet'!D252 -> 516 | D33: 0.4 | E33: =D33*C33 -> 206.4
B34: ='Data Sheet'!C253 -> Investments in associates | C34: ='Data Sheet'!D253 -> 764.1 | D34: 0.25 | E34: =D34*C34 -> 191.025
B35: ='Data Sheet'!C254 -> Intangibles | C35: ='Data Sheet'!D254 -> 99.4 | D35: 0 | E35: =D35*C35 -> 0
B36: ='Data Sheet'!C255 -> Derivatives | C36: ='Data Sheet'!D255 -> 53.6 | D36: 0.5 | E36: =D36*C36 -> 26.8
B37: ='Data Sheet'!C256 -> Total | C37: ='Data Sheet'!D256 -> 0 | E37: =SUM(E28:E36) -> 3208
B40: Recoverable asset value | C40: =E37 -> 3208
B41: Other liabilities | C41: =HistoricalFS!G66-'Scenario Analysis'!C25 -> 2476.8
B42: Residual available to corporate bank lenders | C42: =C40-C41 -> 731.2
B43: Recovery rate | C43: =C42/C25 -> 0.46962107
B47: Receivables : 60%: some collection risk and distress discounts.
B48: Inventory : 40%: distressed liquidation usually requires markdowns.
B49: PP&E : 55%: assets have value, but forced-sale prices can be below book value.
B50: Investment property : 60%: relatively tangible, but distressed sale may require a discount.
B51: Financial assets : 40%: valuation/liquidity uncertainty.
B52: Associates : 25%: minority/investment interests may be difficult to monetise quickly.
B53: Intangibles : 0%: conservative assumption in liquidation.
...

Sheet Data>

Sheet Data Sheet
A3: SOURCE: INVESTING.COM
C5: INCOME STATEMENT
A6: * In Millions of GBP (except for per share items)
A7: Period Ending:
D8: 2022 | E8: 2023 | F8: 2024 | G8: 2025 | H8: 2026
C9: Total Revenues | D9: 4805.3 | E9: 5586 | F9: 5317 | G9: 4900.9 | H9: 5325.9
C10: Total Revenues Growth | D10: 0.3255 | E10: 0.1625 | F10: -0.0482 | G10: -0.0783 | H10: 0.0867
C11: Cost of Revenue | D11: 2708.1 | E11: 3175.5 | F11: 2887.2 | G11: 2587.5 | H11: 2721.6
C12: Gross Profit | D12: 2097.2 | E12: 2410.5 | F12: 2429.8 | G12: 2313.4 | H12: 2604.3
C13: Gross Profit Growth | D13: 0.37 | E13: 0.1494 | F13: 0.008 | G13: -0.0479 | H13: 0.1257
C14: Gross Profit Margin % | D14: 0.4364 | E14: 0.4315 | F14: 0.457 | G14: 0.472 | H14: 0.489
C15: Other Operating Expenses, Total | D15: 1554 | E15: 1961.6 | F15: 1906.6 | G15: 1776.9 | H15: 1975.5
C16: Operating Income | D16: 543.2 | E16: 448.9 | F16: 523.2 | G16: 536.5 | H16: 628.8
C17: Operating Income Growth | D17: 1.1859 | E17: -0.1736 | F17: 0.1655 | G17: 0.0254 | H17: 0.172
C18: EBIT Margin % | D18: 0.113 | E18: 0.0804 | F18: 0.0984 | G18: 0.1095 | H18: 0.1181
C19: Net Interest Expenses | D19: 15.5 | E19: 61.7 | F19: 8.8 | G19: 16.8 | H19: 136.5
C20: Net Interest Expenses Growth | D20: -0.7952 | E20: 2.9806 | F20: -0.8574 | G20: 0.9091 | H20: 7.125
... C35: Net Income Margin % | D35: 0.052 | E35: 0.088 | F35: 0.0716 | G35: 0.0596 | H35: 0.0704
C36: Preferred Dividend and Other Adjustments | D36: - | E36: - | F36: - | G36: - | H36: -
C37: Net Income to Common Excl. Extra Items | D37: 249.8 | E37: 465.4 | F37: 387.3 | G37: 286.3 | H37: 342.6
C38: Basic EPS - Continuing Operations | D38: 0.53 | E38: 1.01 | F38: 0.88 | G38: 0.66 | H38: 0.79
C39: Basic EPS - Continuing Operations Growth | D39: 4.2008 | E39: 0.912 | F39: -0.1272 | G39: -0.2513 | H39: 0.1978
C40: Diluted EPS - Continuing Operations | D40: 0.48 | E40: 1.01 | F40: 0.88 | G40: 0.66 | H40: 0.79
C41: Diluted EPS - Continuing Operations Growth | D41: 3.6099 | E41: 1.1304 | F41: -0.1274 | G41: -0.2511 | H41: 0.1976
C42: Basic Weighted Average Shares Outstanding | D42: 471.98 | E42: 459.91 | F42: 438.5 | G42: 432.93 | H42: 432.5
C43: Diluted Weighted Average Shares Outstanding | D43: 471.98 | E43: 459.91 | F43: 438.5 | G43: 432.93 | H43: 432.5
C44: Dividend Per Share | D44: - | E44: - | F44: - | G44: - | H44: -
C45: Dividend Per Share Growth | D45: - | E45: - | F45: - | G45: - | H45: -
C46: EBITDA | D46: 725.6 | E46: 642.9 | F46: 724.6 | G46: 722.3 | H46: 836.1
C47: EBITDA Growth | D47: 0.5321 | E47: -0.114 | F47: 0.1271 | G47: -0.0032 | H47: 0.1576
C48: EBITDA Margin % | D48: 0.151 | E48: 0.1151 | F48: 0.1363 | G48: 0.1474 | H48: 0.157
C49: EBIT | D49: 543.2 | E49: 448.9 | F49: 523.2 | G49: 536.5 | H49: 628.8
C53: BALANCE SHEET
C54: Period Ending: | D54: 2022 | E54: 2023 | F54: 2024 | G54: 2025 | H54: 2026
B55: * In Millions of GBP (except for per share items)
C56: Total Current Assets | D56: 2612.3 | E56: 2597.2 | F56: 2476 | G56: 2355.6 | H56: 2701.1
C57: Cash & Cash Equivalents | D57: 336.8 | E57: 332.9 | F57: 358.6 | G57: 252.2 | H57: 388.9
C58: Cash & Cash Equivalents Growth | D58: -0.263 | E58: -0.0116 | F58: 0.0772 | G58: -0.2967 | H58: 0.542
C59: Short-Term Investments | D59: - | E59: - | F59: - | G59: - | H59: -
C60: Total Receivables | D60: 485 | E60: 418.5 | F60: 432.5 | G60: 318.1 | H60: 526.9
...
